Workbook

Sheet Data Dictionary
A1: Data Dictionary: BART_Rides
A3: column | B3: description
A4: Date | B4: Date for which exit data was collected.
A5: Station Code | B5: Two-letter code for the BART station. See the StationCodes table/tab for reference on the station names corresponding with each code.
A6: Lines | B6: Abbreviated code for the rail lines on which each station lies, one letter for each line: Y = Yellow, B = Blue, O = Orange, G = Green, R = Red, S = Silver. Lines are always listed in this order. i.e. if a station is on the yellow line, Y will always be the first letter.
A7: Total Passengers | B7: Number of passengers who exited at the corresponding station and date.
A9: Station Codes
A11: Station Code | B11: Station Name
A12: RM | B12: Richmond
A13: EN | B13: El Cerrito Del Norte
A14: EP | B14: El Cerrito Plaza
A15: NB | B15: North Berkeley
A16: BK | B16: Berkeley
A17: AS | B17: Ashby
A18: MA | B18: MacArthur
A19: 19 | B19: 19th Street Oakland
A20: 12 | B20: 12th Street / Oakland City Center
A21: LM | B21: Lake Merritt
A22: FV | B22: Fruitvale | F22: =61-12-4 -> 45
A23: CL | B23: Coliseum
A24: SL | B24: San Leandro
A25: BF | B25: Bayfair
A26: HY | B26: Hayward
A27: SH | B27: South Hayward
A28: UC | B28: Union City
A29: FM | B29: Fremont
A30: CN | B30: Concord
A31: PH | B31: Pleasant Hill
A32: WC | B32: Walnut Creek
A33: LF | B33: Lafayette
A34: OR | B34: Orinda
... A40: CC | B40: Civic Center
A41: 16 | B41: 16th Street Mission
A42: 24 | B42: 24th Street Mission
A43: GP | B43: Glen Park
A44: BP | B44: Balboa Park
A45: DC | B45: Daly City
A46: CM | B46: Colma
A47: CV | B47: Castro Valley
A48: ED | B48: Dublin/Pleasanton
...

Sheet BART Ridership Analysis
A1: Milestone | BART Ridership Analysis | F1: Date | G1: Station Code | H1: Lines | I1: TotalPassengers | J1: Month | K1: DayOfWeek | L1: FirstLetter | M1: YellowLine | N1: Downtown
F2: 44197 | G2: RM | H2: YO | I2: 328 | J2: =MONTH(BART_Rides[[#This Row],[Date]]) -> 1 | K2: =WEEKDAY(BART_Rides[[#This Row],[Date]],2) -> 5 | L2: =LEFT(BART_Rides[[#This Row],[Lines]],1) -> Y | M2: =IF(BART_Rides[[#This Row],[FirstLetter]]="Y","Yes","No") -> Yes | N2: =IF(OR(BART_Rides[[#This Row],[Station Code]]="EM", BART_Rides[[#This Row],[Station Code]]="MT", BART_Rides[[#This Row],[Station Code]]="PL", BART_Rides[[#This Row],[Station Code]]="CC"), "Yes", "No") -> No
A3: • All of your answers should be typed or pasted into the grey boxes. • Questions with grey answer boxes expect a specific answer. Once you input the correct answer, the question number box will change from blue to green. • Questions with yellow answer boxes are free-response questions. There will be no change in the question number boxes (in blue), regardless of your answer. • Hover your cursor over the blue hint box to get a helpful hint! | F3: 44198 | G3: RM | H3: YO | I3: 395 | J3: =MONTH(BART_Rides[[#This Row],[Date]]) -> 1 | K3: =WEEKDAY(BART_Rides[[#This Row],[Date]],2) -> 6 | L3: =LEFT(BART_Rides[[#This Row],[Lines]],1) -> Y | M3: =IF(BART_Rides[[#This Row],[FirstLetter]]="Y","Yes","No") -> Yes | N3: =IF(OR(BART_Rides[[#This Row],[Station Code]]="EM", BART_Rides[[#This Row],[Station Code]]="MT", BART_Rides[[#This Row],[Station Code]]="PL", BART_Rides[[#This Row],[Station Code]]="CC"), "Yes", "No") -> No
F4: 44199 | G4: RM | H4: YO | I4: 366 | J4: =MONTH(BART_Rides[[#This Row],[Date]]) -> 1 | K4: =WEEKDAY(BART_Rides[[#This Row],[Date]],2) -> 7 | L4: =LEFT(BART_Rides[[#This Row],[Lines]],1) -> Y | M4: =IF(BART_Rides[[#This Row],[FirstLetter]]="Y","Yes","No") -> Yes | N4: =IF(OR(BART_Rides[[#This Row],[Station Code]]="EM", BART_Rides[[#This Row],[Station Code]]="MT", BART_Rides[[#This Row],[Station Code]]="PL", BART_Rides[[#This Row],[Station Code]]="CC"), "Yes", "No") -> No
F5: 44200 | G5: RM | H5: YO | I5: 856 | J5: =MONTH(BART_Rides[[#This Row],[Date]]) -> 1 | K5: =WEEKDAY(BART_Rides[[#This Row],[Date]],2) -> 1 | L5: =LEFT(BART_Rides[[#This Row],[Lines]],1) -> Y | M5: =IF(BART_Rides[[#This Row],[FirstLetter]]="Y","Yes","No") -> Yes | N5: =IF(OR(BART_Rides[[#This Row],[Station Code]]="EM", BART_Rides[[#This Row],[Station Code]]="MT", BART_Rides[[#This Row],[Station Code]]="PL", BART_Rides[[#This Row],[Station Code]]="CC"), "Yes", "No") -> No
F6: 44201 | G6: RM | H6: YO | I6: 950 | J6: =MONTH(BART_Rides[[#This Row],[Date]]) -> 1 | K6: =WEEKDAY(BART_Rides[[#This Row],[Date]],2) -> 2 | L6: =LEFT(BART_Rides[[#This Row],[Lines]],1) -> Y | M6: =IF(BART_Rides[[#This Row],[FirstLetter]]="Y","Yes","No") -> Yes | N6: =IF(OR(BART_Rides[[#This Row],[Station Code]]="EM", BART_Rides[[#This Row],[Station Code]]="MT", BART_Rides[[#This Row],[Station Code]]="PL", BART_Rides[[#This Row],[Station Code]]="CC"), "Yes", "No") -> No
F7: 44202 | G7: RM | H7: YO | I7: 934 | J7: =MONTH(BART_Rides[[#This Row],[Date]]) -> 1 | K7: =WEEKDAY(BART_Rides[[#This Row],[Date]],2) -> 3 | L7: =LEFT(BART_Rides[[#This Row],[Lines]],1) -> Y | M7: =IF(BART_Rides[[#This Row],[FirstLetter]]="Y","Yes","No") -> Yes | N7: =IF(OR(BART_Rides[[#This Row],[Station Code]]="EM", BART_Rides[[#This Row],[Station Code]]="MT", BART_Rides[[#This Row],[Station Code]]="PL", BART_Rides[[#This Row],[Station Code]]="CC"), "Yes", "No") -> No
F8: 44203 | G8: RM | H8: YO | I8: 964 | J8: =MONTH(BART_Rides[[#This Row],[Date]]) -> 1 | K8: =WEEKDAY(BART_Rides[[#This Row],[Date]],2) -> 4 | L8: =LEFT(BART_Rides[[#This Row],[Lines]],1) -> Y | M8: =IF(BART_Rides[[#This Row],[FirstLetter]]="Y","Yes","No") -> Yes | N8: =IF(OR(BART_Rides[[#This Row],[Station Code]]="EM", BART_Rides[[#This Row],[Station Code]]="MT", BART_Rides[[#This Row],[Station Code]]="PL", BART_Rides[[#This Row],[Station Code]]="CC"), "Yes", "No") -> No
F9: 44204 | G9: RM | H9: YO | I9: 965 | J9: =MONTH(BART_Rides[[#This Row],[Date]]) -> 1 | K9: =WEEKDAY(BART_Rides[[#This Row],[Date]],2) -> 5 | L9: =LEFT(BART_Rides[[#This Row],[Lines]],1) -> Y | M9: =IF(BART_Rides[[#This Row],[FirstLetter]]="Y","Yes","No") -> Yes | N9: =IF(OR(BART_Rides[[#This Row],[Station Code]]="EM", BART_Rides[[#This Row],[Station Code]]="MT", BART_Rides[[#This Row],[Station Code]]="PL", BART_Rides[[#This Row],[Station Code]]="CC"), "Yes", "No") -> No
F10: 44205 | G10: RM | H10: YO | I10: 532 | J10: =MONTH(BART_Rides[[#This Row],[Date]]) -> 1 | K10: =WEEKDAY(BART_Rides[[#This Row],[Date]],2) -> 6 | L10: =LEFT(BART_Rides[[#This Row],[Lines]],1) -> Y | M10: =IF(BART_Rides[[#This Row],[FirstLetter]]="Y","Yes","No") -> Yes | N10: =IF(OR(BART_Rides[[#This Row],[Station Code]]="EM", BART_Rides[[#This Row],[Station Code]]="MT", BART_Rides[[#This Row],[Station Code]]="PL", BART_Rides[[#This Row],[Station Code]]="CC"), "Yes", "No") -> No
F11: 44206 | G11: RM | H11: YO | I11: 367 | J11: =MONTH(BART_Rides[[#This Row],[Date]]) -> 1 | K11: =WEEKDAY(BART_Rides[[#This Row],[Date]],2) -> 7 | L11: =LEFT(BART_Rides[[#This Row],[Lines]],1) -> Y | M11: =IF(BART_Rides[[#This Row],[FirstLetter]]="Y","Yes","No") -> Yes | N11: =IF(OR(BART_Rides[[#This Row],[Station Code]]="EM", BART_Rides[[#This Row],[Station Code]]="MT", BART_Rides[[#This Row],[Station Code]]="PL", BART_Rides[[#This Row],[Station Code]]="CC"), "Yes", "No") -> No
F12: 44207 | G12: RM | H12: YO | I12: 921 | J12: =MONTH(BART_Rides[[#This Row],[Date]]) -> 1 | K12: =WEEKDAY(BART_Rides[[#This Row],[Date]],2) -> 1 | L12: =LEFT(BART_Rides[[#This Row],[Lines]],1) -> Y | M12: =IF(BART_Rides[[#This Row],[FirstLetter]]="Y","Yes","No") -> Yes | N12: =IF(OR(BART_Rides[[#This Row],[Station Code]]="EM", BART_Rides[[#This Row],[Station Code]]="MT", BART_Rides[[#This Row],[Station Code]]="PL", BART_Rides[[#This Row],[Station Code]]="CC"), "Yes", "No") -> No
F13: 44208 | G13: RM | H13: YO | I13: 966 | J13: =MONTH(BART_Rides[[#This Row],[Date]]) -> 1 | K13: =WEEKDAY(BART_Rides[[#This Row],[Date]],2) -> 2 | L13: =LEFT(BART_Rides[[#This Row],[Lines]],1) -> Y | M13: =IF(BART_Rides[[#This Row],[FirstLetter]]="Y","Yes","No") -> Yes | N13: =IF(OR(BART_Rides[[#This Row],[Station Code]]="EM", BART_Rides[[#This Row],[Station Code]]="MT", BART_Rides[[#This Row],[Station Code]]="PL", BART_Rides[[#This Row],[Station Code]]="CC"), "Yes", "No") -> No
A14: Part 1: Feature Engineering | F14: 44209 | G14: RM | H14: YO | I14: 964 | J14: =MONTH(BART_Rides[[#This Row],[Date]]) -> 1 | K14: =WEEKDAY(BART_Rides[[#This Row],[Date]],2) -> 3 | L14: =LEFT(BART_Rides[[#This Row],[Lines]],1) -> Y | M14: =IF(BART_Rides[[#This Row],[FirstLetter]]="Y","Yes","No") -> Yes | N14: =IF(OR(BART_Rides[[#This Row],[Station Code]]="EM", BART_Rides[[#This Row],[Station Code]]="MT", BART_Rides[[#This Row],[Station Code]]="PL", BART_Rides[[#This Row],[Station Code]]="CC"), "Yes", "No") -> No
F15: 44210 | G15: RM | H15: YO | I15: 948 | J15: =MONTH(BART_Rides[[#This Row],[Date]]) -> 1 | K15: =WEEKDAY(BART_Rides[[#This Row],[Date]],2) -> 4 | L15: =LEFT(BART_Rides[[#This Row],[Lines]],1) -> Y | M15: =IF(BART_Rides[[#This Row],[FirstLetter]]="Y","Yes","No") -> Yes | N15: =IF(OR(BART_Rides[[#This Row],[Station Code]]="EM", BART_Rides[[#This Row],[Station Code]]="MT", BART_Rides[[#This Row],[Station Code]]="PL", BART_Rides[[#This Row],[Station Code]]="CC"), "Yes", "No") -> No
A16: For all the questions below, you'll refer to the dataset to the right. The table is named BART_Rides. | F16: 44211 | G16: RM | H16: YO | I16: 946 | J16: =MONTH(BART_Rides[[#This Row],[Date]]) -> 1 | K16: =WEEKDAY(BART_Rides[[#This Row],[Date]],2) -> 5 | L16: =LEFT(BART_Rides[[#This Row],[Lines]],1) -> Y | M16: =IF(BART_Rides[[#This Row],[FirstLetter]]="Y","Yes","No") -> Yes | N16: =IF(OR(BART_Rides[[#This Row],[Station Code]]="EM", BART_Rides[[#This Row],[Station Code]]="MT", BART_Rides[[#This Row],[Station Code]]="PL", BART_Rides[[#This Row],[Station Code]]="CC"), "Yes", "No") -> No
A17: 1 | B17: In the Month column, extract the month from each date. | D17: Hint! | F17: 44212 | G17: RM | H17: YO | I17: 2 | J17: =MONTH(BART_Rides[[#This Row],[Date]]) -> 1 | K17: =WEEKDAY(BART_Rides[[#This Row],[Date]],2) -> 6 | L17: =LEFT(BART_Rides[[#This Row],[Lines]],1) -> Y | M17: =IF(BART_Rides[[#This Row],[FirstLetter]]="Y","Yes","No") -> Yes | N17: =IF(OR(BART_Rides[[#This Row],[Station Code]]="EM", BART_Rides[[#This Row],[Station Code]]="MT", BART_Rides[[#This Row],[Station Code]]="PL", BART_Rides[[#This Row],[Station Code]]="CC"), "Yes", "No") -> No
A18: 2 | B18: In the DayOfWeek column, extract the day of the week from each date. Note: It will make it easier later in the Miestone if you have Monday = 1 , Sunday = 7. | D18: Hint! | F18: 44213 | G18: RM | H18: YO | I18: 0 | J18: =MONTH(BART_Rides[[#This Row],[Date]]) -> 1 | K18: =WEEKDAY(BART_Rides[[#This Row],[Date]],2) -> 7 | L18: =LEFT(BART_Rides[[#This Row],[Lines]],1) -> Y | M18: =IF(BART_Rides[[#This Row],[FirstLetter]]="Y","Yes","No") -> Yes | N18: =IF(OR(BART_Rides[[#This Row],[Station Code]]="EM", BART_Rides[[#This Row],[Station Code]]="MT", BART_Rides[[#This Row],[Station Code]]="PL", BART_Rides[[#This Row],[Station Code]]="CC"), "Yes", "No") -> No
F19: 44214 | G19: RM | H19: YO | I19: 2 | J19: =MONTH(BART_Rides[[#This Row],[Date]]) -> 1 | K19: =WEEKDAY(BART_Rides[[#This Row],[Date]],2) -> 1 | L19: =LEFT(BART_Rides[[#This Row],[Lines]],1) -> Y | M19: =IF(BART_Rides[[#This Row],[FirstLetter]]="Y","Yes","No") -> Yes | N19: =IF(OR(BART_Rides[[#This Row],[Station Code]]="EM", BART_Rides[[#This Row],[Station Code]]="MT", BART_Rides[[#This Row],[Station Code]]="PL", BART_Rides[[#This Row],[Station Code]]="CC"), "Yes", "No") -> No
A20: In the YellowLine column, we want to capture whether or not a station is on the Yellow Line. We need to do this in two steps: first isolate the relevant letter from the Lines column and then classify the stations based on whether they belong to the Yellow Line. | F20: 44215 | G20: RM | H20: YO | I20: 804 | J20: =MONTH(BART_Rides[[#This Row],[Date]]) -> 1 | K20: =WEEKDAY(BART_Rides[[#This Row],[Date]],2) -> 2 | L20: =LEFT(BART_Rides[[#This Row],[Lines]],1) -> Y | M20: =IF(BART_Rides[[#This Row],[FirstLetter]]="Y","Yes","No") -> Yes | N20: =IF(OR(BART_Rides[[#This Row],[Station Code]]="EM", BART_Rides[[#This Row],[Station Code]]="MT", BART_Rides[[#This Row],[Station Code]]="PL", BART_Rides[[#This Row],[Station Code]]="CC"), "Yes", "No") -> No
F21: 44216 | G21: RM | H21: YO | I21: 909 | J21: =MONTH(BART_Rides[[#This Row],[Date]]) -> 1 | K21: =WEEKDAY(BART_Rides[[#This Row],[Date]],2) -> 3 | L21: =LEFT(BART_Rides[[#This Row],[Lines]],1) -> Y | M21: =IF(BART_Rides[[#This Row],[FirstLetter]]="Y","Yes","No") -> Yes | N21: =IF(OR(BART_Rides[[#This Row],[Station Code]]="EM", BART_Rides[[#This Row],[Station Code]]="MT", BART_Rides[[#This Row],[Station Code]]="PL", BART_Rides[[#This Row],[Station Code]]="CC"), "Yes", "No") -> No
A22: 3 | B22: In the FirstLetter column, extract the first letter from the Lines column. e.g. "YO" should output "Y". | D22: Hint! | F22: 44217 | G22: RM | H22: YO | I22: 982 | J22: =MONTH(BART_Rides[[#This Row],[Date]]) -> 1 | K22: =WEEKDAY(BART_Rides[[#This Row],[Date]],2) -> 4 | L22: =LEFT(BART_Rides[[#This Row],[Lines]],1) -> Y | M22: =IF(BART_Rides[[#This Row],[FirstLetter]]="Y","Yes","No") -> Yes | N22: =IF(OR(BART_Rides[[#This Row],[Station Code]]="EM", BART_Rides[[#This Row],[Station Code]]="MT", BART_Rides[[#This Row],[Station Code]]="PL", BART_Rides[[#This Row],[Station Code]]="CC"), "Yes", "No") -> No
F23: 44218 | G23: RM | H23: YO | I23: 945 | J23: =MONTH(BART_Rides[[#This Row],[Date]]) -> 1 | K23: =WEEKDAY(BART_Rides[[#This Row],[Date]],2) -> 5 | L23: =LEFT(BART_Rides[[#This Row],[Lines]],1) -> Y | M23: =IF(BART_Rides[[#This Row],[FirstLetter]]="Y","Yes","No") -> Yes | N23: =IF(OR(BART_Rides[[#This Row],[Station Code]]="EM", BART_Rides[[#This Row],[Station Code]]="MT", BART_Rides[[#This Row],[Station Code]]="PL", BART_Rides[[#This Row],[Station Code]]="CC"), "Yes", "No") -> No
A24: 4 | B24: In the YellowLine column, extract whether or not a station is on the Yellow Line: "Yes" if it is on the Yellow Line, and "No" if it is not. Based on the Data Dictionary, a station is on the Yellow line if the first letter of the Lines string is a Y. | D24: Hint! | F24: 44219 | G24: RM | H24: YO | I24: 523 | J24: =MONTH(BART_Rides[[#This Row],[Date]]) -> 1 | K24: =WEEKDAY(BART_Rides[[#This Row],[Date]],2) -> 6 | L24: =LEFT(BART_Rides[[#This Row],[Lines]],1) -> Y | M24: =IF(BART_Rides[[#This Row],[FirstLetter]]="Y","Yes","No") -> Yes | N24: =IF(OR(BART_Rides[[#This Row],[Station Code]]="EM", BART_Rides[[#This Row],[Station Code]]="MT", BART_Rides[[#This Row],[Station Code]]="PL", BART_Rides[[#This Row],[Station Code]]="CC"), "Yes", "No") -> No
F25: 44220 | G25: RM | H25: YO | I25: 310 | J25: =MONTH(BART_Rides[[#This Row],[Date]]) -> 1 | K25: =WEEKDAY(BART_Rides[[#This Row],[Date]],2) -> 7 | L25: =LEFT(BART_Rides[[#This Row],[Lines]],1) -> Y | M25: =IF(BART_Rides[[#This Row],[FirstLetter]]="Y","Yes","No") -> Yes | N25: =IF(OR(BART_Rides[[#This Row],[Station Code]]="EM", BART_Rides[[#This Row],[Station Code]]="MT", BART_Rides[[#This Row],[Station Code]]="PL", BART_Rides[[#This Row],[Station Code]]="CC"), "Yes", "No") -> No
F26: 44221 | G26: RM | H26: YO | I26: 988 | J26: =MONTH(BART_Rides[[#This Row],[Date]]) -> 1 | K26: =WEEKDAY(BART_Rides[[#This Row],[Date]],2) -> 1 | L26: =LEFT(BART_Rides[[#This Row],[Lines]],1) -> Y | M26: =IF(BART_Rides[[#This Row],[FirstLetter]]="Y","Yes","No") -> Yes | N26: =IF(OR(BART_Rides[[#This Row],[Station Code]]="EM", BART_Rides[[#This Row],[Station Code]]="MT", BART_Rides[[#This Row],[Station Code]]="PL", BART_Rides[[#This Row],[Station Code]]="CC"), "Yes", "No") -> No
A27: Prompt ChatGPT: Provide the Excel IF function to check if the first letter of a string is 'Y' and return 'Yes' if true, and 'No' if false. Explain each part of the fomula to me. | F27: 44222 | G27: RM | H27: YO | I27: 909 | J27: =MONTH(BART_Rides[[#This Row],[Date]]) -> 1 | K27: =WEEKDAY(BART_Rides[[#This Row],[Date]],2) -> 2 | L27: =LEFT(BART_Rides[[#This Row],[Lines]],1) -> Y | M27: =IF(BART_Rides[[#This Row],[FirstLetter]]="Y","Yes","No") -> Yes | N27: =IF(OR(BART_Rides[[#This Row],[Station Code]]="EM", BART_Rides[[#This Row],[Station Code]]="MT", BART_Rides[[#This Row],[Station Code]]="PL", BART_Rides[[#This Row],[Station Code]]="CC"), "Yes", "No") -> No
F28: 44223 | G28: RM | H28: YO | I28: 888 | J28: =MONTH(BART_Rides[[#This Row],[Date]]) -> 1 | K28: =WEEKDAY(BART_Rides[[#This Row],[Date]],2) -> 3 | L28: =LEFT(BART_Rides[[#This Row],[Lines]],1) -> Y | M28: =IF(BART_Rides[[#This Row],[FirstLetter]]="Y","Yes","No") -> Yes | N28: =IF(OR(BART_Rides[[#This Row],[Station Code]]="EM", BART_Rides[[#This Row],[Station Code]]="MT", BART_Rides[[#This Row],[Station Code]]="PL", BART_Rides[[#This Row],[Station Code]]="CC"), "Yes", "No") -> No
F29: 44224 | G29: RM | H29: YO | I29: 866 | J29: =MONTH(BART_Rides[[#This Row],[Date]]) -> 1 | K29: =WEEKDAY(BART_Rides[[#This Row],[Date]],2) -> 4 | L29: =LEFT(BART_Rides[[#This Row],[Lines]],1) -> Y | M29: =IF(BART_Rides[[#This Row],[FirstLetter]]="Y","Yes","No") -> Yes | N29: =IF(OR(BART_Rides[[#This Row],[Station Code]]="EM", BART_Rides[[#This Row],[Station Code]]="MT", BART_Rides[[#This Row],[Station Code]]="PL", BART_Rides[[#This Row],[Station Code]]="CC"), "Yes", "No") -> No
A30: Part 2: Key Ridership Metrics | F30: 44225 | G30: RM | H30: YO | I30: 1000 | J30: =MONTH(BART_Rides[[#This Row],[Date]]) -> 1 | K30: =WEEKDAY(BART_Rides[[#This Row],[Date]],2) -> 5 | L30: =LEFT(BART_Rides[[#This Row],[Lines]],1) -> Y | M30: =IF(BART_Rides[[#This Row],[FirstLetter]]="Y","Yes","No") -> Yes | N30: =IF(OR(BART_Rides[[#This Row],[Station Code]]="EM", BART_Rides[[#This Row],[Station Code]]="MT", BART_Rides[[#This Row],[Station Code]]="PL", BART_Rides[[#This Row],[Station Code]]="CC"), "Yes", "No") -> No
F31: 44226 | G31: RM | H31: YO | I31: 1 | J31: =MONTH(BART_Rides[[#This Row],[Date]]) -> 1 | K31: =WEEKDAY(BART_Rides[[#This Row],[Date]],2) -> 6 | L31: =LEFT(BART_Rides[[#This Row],[Lines]],1) -> Y | M31: =IF(BART_Rides[[#This Row],[FirstLetter]]="Y","Yes","No") -> Yes | N31: =IF(OR(BART_Rides[[#This Row],[Station Code]]="EM", BART_Rides[[#This Row],[Station Code]]="MT", BART_Rides[[#This Row],[Station Code]]="PL", BART_Rides[[#This Row],[Station Code]]="CC"), "Yes", "No") -> No
A32: 5 | B32: Use the SUM() function and the Total Passengers column to find out how many total passengers rode BART in all of 2021. This is the baseline ridership metric. | C32: =SUM(BART_Rides[TotalPassengers]) -> 24583309 | F32: 44227 | G32: RM | H32: YO | I32: 1 | J32: =MONTH(BART_Rides[[#This Row],[Date]]) -> 1 | K32: =WEEKDAY(BART_Rides[[#This Row],[Date]],2) -> 7 | L32: =LEFT(BART_Rides[[#This Row],[Lines]],1) -> Y | M32: =IF(BART_Rides[[#This Row],[FirstLetter]]="Y","Yes","No") -> Yes | N32: =IF(OR(BART_Rides[[#This Row],[Station Code]]="EM", BART_Rides[[#This Row],[Station Code]]="MT", BART_Rides[[#This Row],[Station Code]]="PL", BART_Rides[[#This Row],[Station Code]]="CC"), "Yes", "No") -> No
F33: 44228 | G33: RM | H33: YO | I33: 975 | J33: =MONTH(BART_Rides[[#This Row],[Date]]) -> 2 | K33: =WEEKDAY(BART_Rides[[#This Row],[Date]],2) -> 1 | L33: =LEFT(BART_Rides[[#This Row],[Lines]],1) -> Y | M33: =IF(BART_Rides[[#This Row],[FirstLetter]]="Y","Yes","No") -> Yes | N33: =IF(OR(BART_Rides[[#This Row],[Station Code]]="EM", BART_Rides[[#This Row],[Station Code]]="MT", BART_Rides[[#This Row],[Station Code]]="PL", BART_Rides[[#This Row],[Station Code]]="CC"), "Yes", "No") -> No
A34: 6 | B34: How many total passengers rode during a weekday? | C34: =SUMIF(BART_Rides[DayOfWeek],"<6", BART_Rides[TotalPassengers]) -> 20281852 | D34: Hint! | F34: 44229 | G34: RM | H34: YO | I34: 978 | J34: =MONTH(BART_Rides[[#This Row],[Date]]) -> 2 | K34: =WEEKDAY(BART_Rides[[#This Row],[Date]],2) -> 2 | L34: =LEFT(BART_Rides[[#This Row],[Lines]],1) -> Y | M34: =IF(BART_Rides[[#This Row],[FirstLetter]]="Y","Yes","No") -> Yes | N34: =IF(OR(BART_Rides[[#This Row],[Station Code]]="EM", BART_Rides[[#This Row],[Station Code]]="MT", BART_Rides[[#This Row],[Station Code]]="PL", BART_Rides[[#This Row],[Station Code]]="CC"), "Yes", "No") -> No
A35: 7 | B35: What proportion of all passengers rode the BART on the weekday? Remember: The proportion is calculated by dividing the total number of passengers who rode on a weekday by the total number of passengers who rode on the BART. | C35: =C34/C32 -> 0.8250253 | F35: 44230 | G35: RM | H35: YO | I35: 1057 | J35: =MONTH(BART_Rides[[#This Row],[Date]]) -> 2 | K35: =WEEKDAY(BART_Rides[[#This Row],[Date]],2) -> 3 | L35: =LEFT(BART_Rides[[#This Row],[Lines]],1) -> Y | M35: =IF(BART_Rides[[#This Row],[FirstLetter]]="Y","Yes","No") -> Yes | N35: =IF(OR(BART_Rides[[#This Row],[Station Code]]="EM", BART_Rides[[#This Row],[Station Code]]="MT", BART_Rides[[#This Row],[Station Code]]="PL", BART_Rides[[#This Row],[Station Code]]="CC"), "Yes", "No") -> No
F36: 44231 | G36: RM | H36: YO | I36: 1038 | J36: =MONTH(BART_Rides[[#This Row],[Date]]) -> 2 | K36: =WEEKDAY(BART_Rides[[#This Row],[Date]],2) -> 4 | L36: =LEFT(BART_Rides[[#This Row],[Lines]],1) -> Y | M36: =IF(BART_Rides[[#This Row],[FirstLetter]]="Y","Yes","No") -> Yes | N36: =IF(OR(BART_Rides[[#This Row],[Station Code]]="EM", BART_Rides[[#This Row],[Station Code]]="MT", BART_Rides[[#This Row],[Station Code]]="PL", BART_Rides[[#This Row],[Station Code]]="CC"), "Yes", "No") -> No
F37: 44232 | G37: RM | H37: YO | I37: 1029 | J37: =MONTH(BART_Rides[[#This Row],[Date]]) -> 2 | K37: =WEEKDAY(BART_Rides[[#This Row],[Date]],2) -> 5 | L37: =LEFT(BART_Rides[[#This Row],[Lines]],1) -> Y | M37: =IF(BART_Rides[[#This Row],[FirstLetter]]="Y","Yes","No") -> Yes | N37: =IF(OR(BART_Rides[[#This Row],[Station Code]]="EM", BART_Rides[[#This Row],[Station Code]]="MT", BART_Rides[[#This Row],[Station Code]]="PL", BART_Rides[[#This Row],[Station Code]]="CC"), "Yes", "No") -> No
A38: 8 | B38: What proportion of all passengers rode the BART on the weekend? | C38: =(C32-C34)/C32 -> 0.1749747 | F38: 44233 | G38: RM | H38: YO | I38: 581 | J38: =MONTH(BART_Rides[[#This Row],[Date]]) -> 2 | K38: =WEEKDAY(BART_Rides[[#This Row],[Date]],2) -> 6 | L38: =LEFT(BART_Rides[[#This Row],[Lines]],1) -> Y | M38: =IF(BART_Rides[[#This Row],[FirstLetter]]="Y","Yes","No") -> Yes | N38: =IF(OR(BART_Rides[[#This Row],[Station Code]]="EM", BART_Rides[[#This Row],[Station Code]]="MT", BART_Rides[[#This Row],[Station Code]]="PL", BART_Rides[[#This Row],[Station Code]]="CC"), "Yes", "No") -> No
A39: 9 | B39: How many passengers rode on the Yellow Line? | C39: =SUMIF(BART_Rides[YellowLine], "Yes", BART_Rides[TotalPassengers]) -> 19425399 | D39: Hint! | F39: 44234 | G39: RM | H39: YO | I39: 400 | J39: =MONTH(BART_Rides[[#This Row],[Date]]) -> 2 | K39: =WEEKDAY(BART_Rides[[#This Row],[Date]],2) -> 7 | L39: =LEFT(BART_Rides[[#This Row],[Lines]],1) -> Y | M39: =IF(BART_Rides[[#This Row],[FirstLetter]]="Y","Yes","No") -> Yes | N39: =IF(OR(BART_Rides[[#This Row],[Station Code]]="EM", BART_Rides[[#This Row],[Station Code]]="MT", BART_Rides[[#This Row],[Station Code]]="PL", BART_Rides[[#This Row],[Station Code]]="CC"), "Yes", "No") -> No
A40: 10 | B40: What proportion of all passengers ended on a station on the Yellow Line? Remember: The proportion is calculated by dividing the total number of passengers who rode on a Yellow Line by the total number of passengers who rode on the BART. | C40: =C39/C32 -> 0.7901865 | F40: 44235 | G40: RM | H40: YO | I40: 1033 | J40: =MONTH(BART_Rides[[#This Row],[Date]]) -> 2 | K40: =WEEKDAY(BART_Rides[[#This Row],[Date]],2) -> 1 | L40: =LEFT(BART_Rides[[#This Row],[Lines]],1) -> Y | M40: =IF(BART_Rides[[#This Row],[FirstLetter]]="Y","Yes","No") -> Yes | N40: =IF(OR(BART_Rides[[#This Row],[Station Code]]="EM", BART_Rides[[#This Row],[Station Code]]="MT", BART_Rides[[#This Row],[Station Code]]="PL", BART_Rides[[#This Row],[Station Code]]="CC"), "Yes", "No") -> No
...

Sheet Solutions
A1: Question | B1: Value | C1: Tolerance | D1: student-solution | E1: student-formula
A2: 1 | B2: ="Summary:"&"6.52611910018250" -> Summary:6.52611910018250 | D2: ="Summary:"&IF(ISBLANK(INDEX(BART_Rides[[#This Row],[Month]],1,1)),"no value",ROUND(AVERAGE(BART_Rides[Month]),4)&SUM(BART_Rides[Month])&COUNT(BART_Rides[Month])) -> Summary:6.52611910018250 | E2: =IFERROR(_xlfn.FORMULATEXT(INDEX(BART_Rides[[#This Row],[Month]],1,1)),"no formula") -> =MONTH([@Date])
A3: 2 | B3: Summary:4.00277305018250 | D3: ="Summary:"&IF(ISBLANK(INDEX(BART_Rides[[#This Row],[DayOfWeek]],1,1)),"no value",ROUND(AVERAGE(BART_Rides[DayOfWeek]),4)&SUM(BART_Rides[DayOfWeek])&COUNT(BART_Rides[DayOfWeek])) -> Summary:4.00277305018250 | E3: =IFERROR(_xlfn.FORMULATEXT(INDEX(BART_Rides[[#This Row],[DayOfWeek]],1,1)),"no formula") -> =WEEKDAY([@Date],2)
A4: 3 | B4: Summary:18250 | D4: ="Summary:"&COUNTA(BART_Rides[FirstLetter]) -> Summary:18250 | E4: =IFERROR(_xlfn.FORMULATEXT(INDEX(BART_Rides[[#This Row],[FirstLetter]],1,1)),"no formula") -> =LEFT([@Lines],1)
A5: 4 | B5: Summary:124105840 | D5: ="Summary:"&COUNTIF(BART_Rides[YellowLine],"Yes")&COUNTIF(BART_Rides[YellowLine],"No") -> Summary:124105840 | E5: =IFERROR(_xlfn.FORMULATEXT(INDEX(BART_Rides[[#This Row],[YellowLine]],1,1)),"no formula") -> =IF([@FirstLetter]="Y","Yes","No")
A6: 5 | B6: 24583309 | C6: 0 | D6: =IF(ISBLANK(INDEX('BART Ridership Analysis'!$C$32,1,1)), "no solution", IF(ISERROR(INDEX('BART Ridership Analysis'!$C$32,1,1)), "error in parsing the solution", INDEX('BART Ridership Analysis'!$C$32,1,1))) -> 24583309 | E6: =IFERROR(_xlfn.FORMULATEXT(INDEX('BART Ridership Analysis'!$C$32,1,1)),"no formula") -> =SUM(BART_Rides[TotalPassengers])
A7: 6 | B7: 20281852 | C7: 0 | D7: =IF(ISBLANK(INDEX('BART Ridership Analysis'!$C$34,1,1)), "no solution", IF(ISERROR(INDEX('BART Ridership Analysis'!$C$34,1,1)), "error in parsing the solution", INDEX('BART Ridership Analysis'!$C$34,1,1))) -> 20281852 | E7: =IFERROR(_xlfn.FORMULATEXT(INDEX('BART Ridership Analysis'!$C$34,1,1)),"no formula") -> =SUMIF(BART_Rides[DayOfWeek],"<6", BART_Rides[TotalPassengers])
A8: 7 | B8: 0.825 | C8: 0.1 | D8: =IF(ISBLANK(INDEX('BART Ridership Analysis'!$C$35,1,1)), "no solution", IF(ISERROR(INDEX('BART Ridership Analysis'!$C$35,1,1)), "error in parsing the solution", INDEX('BART Ridership Analysis'!$C$35,1,1))) -> 0.8250253 | E8: =IFERROR(_xlfn.FORMULATEXT(INDEX('BART Ridership Analysis'!$C$35,1,1)),"no formula") -> =C34/C32
A9: 8 | B9: 0.175 | C9: 0.1 | D9: =IF(ISBLANK(INDEX('BART Ridership Analysis'!$C$38,1,1)), "no solution", IF(ISERROR(INDEX('BART Ridership Analysis'!$C$38,1,1)), "error in parsing the solution", INDEX('BART Ridership Analysis'!$C$38,1,1))) -> 0.1749747 | E9: =IFERROR(_xlfn.FORMULATEXT(INDEX('BART Ridership Analysis'!$C$38,1,1)),"no formula") -> =(C32-C34)/C32
A10: 9 | B10: 19425399 | C10: 0 | D10: =IF(ISBLANK(INDEX('BART Ridership Analysis'!$C$39,1,1)), "no solution", IF(ISERROR(INDEX('BART Ridership Analysis'!$C$39,1,1)), "error in parsing the solution", INDEX('BART Ridership Analysis'!$C$39,1,1))) -> 19425399 | E10: =IFERROR(_xlfn.FORMULATEXT(INDEX('BART Ridership Analysis'!$C$39,1,1)),"no formula") -> =SUMIF(BART_Rides[YellowLine], "Yes", BART_Rides[TotalPassengers])
A11: 10 | B11: 0.79 | C11: 0.1 | D11: =IF(ISBLANK(INDEX('BART Ridership Analysis'!$C$40,1,1)), "no solution", IF(ISERROR(INDEX('BART Ridership Analysis'!$C$40,1,1)), "error in parsing the solution", INDEX('BART Ridership Analysis'!$C$40,1,1))) -> 0.7901865 | E11: =IFERROR(_xlfn.FORMULATEXT(INDEX('BART Ridership Analysis'!$C$40,1,1)),"no formula") -> =C39/C32
A12: 11 | B12: free response | D12: =IF(ISBLANK(INDEX('BART Ridership Analysis'!$A$50:$C$54,1,1)), "no solution", IF(ISERROR(INDEX('BART Ridership Analysis'!$A$50:$C$54,1,1)), "error in parsing the solution", INDEX('BART Ridership Analysis'!$A$50:$C$54,1,1))) -> The difference could be for a multitude of reasons. For students, appointments and errands, and work, most of these responsibilities end up on a weekday, and need transportation assistance. However, since school and most major appointments are closed over the weekends, there isn't much demand for the rail. Furthermore, most people go on trips over the weekends, which requires a car or plane, not requiring a railway. BART should optimize for both the weekdays and weekends by adding extra service and extra prep time for the weekdays, as they are the busiest. This includes extra staff members, extra security in case if anything goes awry, and extra cleaners to keep the railway safe and clean. For the weekend, the railway could optimize by reducing the amount of staff onboard, as there are a lot less passengers. If you want to increase sales over the weekends you could drop weekend prices and possibly put up signs and locations of events where railways might take customers close to.
A13: 12 | B13: free response | D13: =IF(ISBLANK(INDEX('BART Ridership Analysis'!$A$58:$C$62,1,1)), "no solution", IF(ISERROR(INDEX('BART Ridership Analysis'!$A$58:$C$62,1,1)), "error in parsing the solution", INDEX('BART Ridership Analysis'!$A$58:$C$62,1,1))) -> I would like to evaluate the amount of Yellow Line railways there are as well as the amount of staff, how they run the yellow line stations, if the yellow lines are faster than other lines, as well as what are the most popular yellow line destinations. This could help expand new Yellow Lines and improve others if they are found to be more efficient. However, if it is just a simple case of more yellow lines than not I suggest expanding other lines if the company would like any other lines.
A14: 13 | B14: Summary:146016790 | D14: ="Summary:"&IF(ISBLANK(INDEX(BART_Rides[[#This Row],[Downtown]],1,1)),"no value",COUNTIF(BART_Rides[Downtown],"Yes")&COUNTIF(BART_Rides[Downtown],"No")) -> Summary:146016790 | E14: =IFERROR(_xlfn.FORMULATEXT(INDEX(BART_Rides[[#This Row],[Downtown]],1,1)),"no formula") -> =IF(OR([@[Station Code]]="EM", [@[Station Code]]="MT", [@[Station Code]]="PL", [@[Station Code]]="CC"), "Yes", "No")
A15: 14 | B15: 6932181 | C15: 0 | D15: =IF(ISBLANK(INDEX('BART Ridership Analysis'!$C$68,1,1)), "no solution", IF(ISERROR(INDEX('BART Ridership Analysis'!$C$68,1,1)), "error in parsing the solution", INDEX('BART Ridership Analysis'!$C$68,1,1))) -> 6932181 | E15: =IFERROR(_xlfn.FORMULATEXT(INDEX('BART Ridership Analysis'!$C$68,1,1)),"no formula") -> =SUMIF(BART_Rides[Downtown], "Yes", BART_Rides[TotalPassengers])
A16: 15 | B16: 0.282 | C16: 0.1 | D16: =IF(ISBLANK(INDEX('BART Ridership Analysis'!$C$69,1,1)), "no solution", IF(ISERROR(INDEX('BART Ridership Analysis'!$C$69,1,1)), "error in parsing the solution", INDEX('BART Ridership Analysis'!$C$69,1,1))) -> 0.2819873 | E16: =IFERROR(_xlfn.FORMULATEXT(INDEX('BART Ridership Analysis'!$C$69,1,1)),"no formula") -> =C68/C32
A17: 16 | B17: free response | D17: =IF(ISBLANK(INDEX('BART Ridership Analysis'!$A$72:$C$76,1,1)), "no solution", IF(ISERROR(INDEX('BART Ridership Analysis'!$A$72:$C$76,1,1)), "error in parsing the solution", INDEX('BART Ridership Analysis'!$A$72:$C$76,1,1))) -> Although the ridership to downtown is only at 28.2%, 28.2% of all 49 stations comes from these 4 downtown stations, which is incredible total passenger volume. If you break down the math, since the rest of the no downtown areas comes around 71.8%, that means each downtown station brings roughly 7.05% (if distributed evenly) while each non-downtown area only brings in around 1.6% (if distributed evenly). Although it is not the majority percentage these stations should have higher prioritization as they have greater total passenger volume. This also means greater service scheduling as there would be more wear and tear on these stations, although that does not mean the other stations should be neglected.
